Workbook

Sheet Cover_Assumptions
A1: Alcon Vision Care Franchise - F27 Portfolio Investment Analysis
A2: Cover & Assumptions
A3: Prepared for: Senior Manager, Global Business Strategy & Planning - Interview Case Study
A6: Shared Structural Assumptions
A7: Driver | B7: Value | C7: Source / Basis
A8: Time horizon (years) | B8: 5 | C8: Project scoping decision - fresh 5-yr incremental window starting FY27 for both options, apples-to-apples comparison
A9: Start year | B9: 2027 | C9: FY27 - fresh incremental decision point, not anchored to Trytyr's actual Q3 2025 launch
A10: Discount rate (WACC proxy) | B10: 0.09 | C10: Source: Industry benchmark - large-cap healthcare/medtech WACC typically 8-10%; midpoint used as estimate, not Alcon-disclosed
A11: Do-nothing baseline methodology | B11: Organic/current trajectory (not zero) - see respective Option tabs | C11: Project scoping decision - isolates incremental investment impact rather than overstating opportunity vs. a zero baseline
A14: Option A: Tryptyr Commercial Accelaration - Assumptions
A15: Driver | B15: Base | C15: Upside | D15: Downside | E15: Source / Basis
A16: Peak share of $7.1B global DED market | B16: 0.05 | C16: 0.075 | D16: 0.03 | E16: Triangulated from Xiidra's ~$400M peak sales / ~$7-8B market at the time = ~5% share
A17: Ramp shape (static across scenarios) | B17: Slow Y1 --> steep Y2-3 inflection --> plateau Y3-4 | E17: Xiidra's real quarterly trail: ~$16M/qtr (Y1, ~2017) --> ~$93M/qtr (Y2, ~2018) --> ~$390-400M annual plateau (Y3-4)
A18: Patent-protected window (years) | B18: 5-7 | E18: Third-party analyst estimate - NOT Alcon-disclosed, flag as estimate
A19: Commercial spend ratio (% of incremental revenue) | B19: 0.225 | E19: Specialty pharma S&M benchmark (life sciences SG&A 25-40% of revenue, ~85% of that is S&M --> ~21-34%; midpoint of lower/specialty end range used)
A20: Organic (do-nothing) peak share of $7.1B global DED market | B20: 0.02 | E20: Reasoned judgment call — organic trajectory without incremental investment. Set below all Invest-case scenarios (including Downside at 3%) to preserve a non-zero incremental benefit even in the worst case; avoids a Downside scenario where the investment shows no advantage over doing nothing.
A23: Option B: Contact Lens Parameter Expansion - Assumptions
A24: Driver | B24: Base | C24: Upside | D24: Downside | E24: Source / Basis
A25: Share-of-toric-segment gain, 5yr (on $4.4B 2025 toric segment) | B25: 0.0075 | C25: 0.015 | D25: 0.0025 | E25: Reasoned/conservative judgement call post-pivot (see toric segment saturation analysis) - NOT a hard data point, document as such
A26: Ramp shape (static across scenarios) | B26: Faster than Tryptyr, ceiling ~Year 2-3 | E26: Qualitative: existing trusted franchise, no de-novo prescribing behavior, 99% first-fit success reduces friction (PRECISION1-for-Astigmatism comp)
A27: Commercial spend ratio (% of incremental revenue, static across scenarios) | B27: 0.125 | E27: Lower than Tryptyr - leverages existing ECP/distribution relationships, no new sales infrastructure needed
A28: Alcon's current share of $4.4B toric segment | B28: 0.18 | E28: Reasoned judgment call — Alcon is one of four major competitors (J&J, CooperVision, Bausch+Lomb, Alcon) in the toric segment; estimated modestly below an even four-way split (25%) given strong underlying momentum (PRECISION1 was fastest-growing US daily disposable pre-toric-launch, 3 toric SKUs launched in 24 months) but not assumed to be category leader. Not a hard data point — Alcon's actual toric-specific share is not disclosed.

Sheet Option_A_Tryptyr
A1: Option A: Tryptyr Commercial Acceleration - Model
A2: ($ in billions unless otherwise noted)
A4: Active Scenario: | B4: Base
A6: Driver | B6: FY27 | C6: FY28 | D6: FY29 | E6: FY30 | F6: FY31
A7: Global DED Market CAGR | B7: 0.066
A8: Global DED Market Size ($B) | B8: 7.1 | C8: =B8*(1+$B$7) -> 7.5686 | D8: =C8*(1+$B$7) -> 8.0681276 | E8: =D8*(1+$B$7) -> 8.600624 | F8: =E8*(1+$B$7) -> 9.1682652
A9: Active Peak Share (resolved from toggle) | B9: =INDEX(Cover_Assumptions!B16:D16,MATCH($B$4,Cover_Assumptions!B15:D15,0)) -> 0.05
A10: Ramp % of Peak Share | B10: 0.15 | C10: 0.5 | D10: 0.85 | E10: 1 | F10: 1
A11: Invest Case Revenue ($B) | B11: =B8*$B$9*B10 -> 0.05325 | C11: =C8*$B$9*C10 -> 0.189215 | D11: =D8*$B$9*D10 -> 0.34289542 | E11: =E8*$B$9*E10 -> 0.4300312 | F11: =F8*$B$9*F10 -> 0.45841326
A12: Organic (Do-Nothing) Peak Share | B12: =Cover_Assumptions!B20 -> 0.02
A13: Organic Ramp % of Peak | B13: 0.08 | C13: 0.25 | D13: 0.5 | E13: 0.75 | F13: 1
A14: Do-Nothing Case Revenue ($B) | B14: =B8*$B$12*B13 -> 0.01136 | C14: =C8*$B$12*C13 -> 0.037843 | D14: =D8*$B$12*D13 -> 0.080681276 | E14: =E8*$B$12*E13 -> 0.12900936 | F14: =F8*$B$12*F13 -> 0.1833653
A16: Incremental Revenue ($B) | B16: =B11-B14 -> 0.04189 | C16: =C11-C14 -> 0.151372 | D16: =D11-D14 -> 0.26221415 | E16: =E11-E14 -> 0.30102184 | F16: =F11-F14 -> 0.27504796
A17: Commercial Spend ($B) | B17: =B16*Cover_Assumptions!$B$19 -> 0.00942525 | C17: =C16*Cover_Assumptions!$B$19 -> 0.0340587 | D17: =D16*Cover_Assumptions!$B$19 -> 0.058998183 | E17: =E16*Cover_Assumptions!$B$19 -> 0.067729914 | F17: =F16*Cover_Assumptions!$B$19 -> 0.06188579
A18: Net Incremental Cash Flow ($B) | B18: =B16-B17 -> 0.03246475 | C18: =C16-C17 -> 0.1173133 | D18: =D16-D17 -> 0.20321596 | E18: =E16-E17 -> 0.23329193 | F18: =F16-F17 -> 0.21316217
A20: Year Index | B20: 1 | C20: =B20+1 -> 2 | D20: =C20+1 -> 3 | E20: =D20+1 -> 4 | F20: =E20+1 -> 5
A21: NPV & Returns
A22: Discount Factor | B22: =1/(1+Cover_Assumptions!$B$10)^B20 -> 0.91743119 | C22: =1/(1+Cover_Assumptions!$B$10)^C20 -> 0.84167999 | D22: =1/(1+Cover_Assumptions!$B$10)^D20 -> 0.77218348 | E22: =1/(1+Cover_Assumptions!$B$10)^E20 -> 0.70842521 | F22: =1/(1+Cover_Assumptions!$B$10)^F20 -> 0.64993139
A23: PV of Net Incremental Cash Flow ($B) | B23: =B18*B22 -> 0.029784174 | C23: =C18*C22 -> 0.098740258 | D23: =D18*D22 -> 0.15692001 | E23: =E18*E22 -> 0.16526988 | F23: =F18*F22 -> 0.13854078
A24: Cumulative PV of Net Incremental Cash Flow | B24: =B23 -> 0.029784174 | C24: =C23+B24 -> 0.12852443 | D24: =D23+C24 -> 0.28544444 | E24: =E23+D24 -> 0.45071432 | F24: =F23+E24 -> 0.58925511
A26: NPV - Option A (Tryptyr), 5-Year ($B) | B26: =SUM(B23:F23) -> 0.58925511
A29: Sensitivity Analysis - NPV ($B) vs. Peak Share & Commercial Spend Ratio
B30: =B26 -> 0.58925511 | C30: 0.03 | D30: 0.035 | E30: 0.04 | F30: 0.045 | G30: 0.05 | H30: 0.055 | I30: 0.06 | J30: 0.065 | K30: 0.07 | L30: 0.075
B31: 0.1 | C31: =INDEX($G$45:$G$54,MATCH(C$30,$A$45:$A$54,0))*(1-$B31) -> 0.29712634 | D31: =INDEX($G$45:$G$54,MATCH(D$30,$A$45:$A$54,0))*(1-$B31) -> 0.39391882 | E31: =INDEX($G$45:$G$54,MATCH(E$30,$A$45:$A$54,0))*(1-$B31) -> 0.4907113 | F31: =INDEX($G$45:$G$54,MATCH(F$30,$A$45:$A$54,0))*(1-$B31) -> 0.58750377 | G31: =INDEX($G$45:$G$54,MATCH(G$30,$A$45:$A$54,0))*(1-$B31) -> 0.68429625 | H31: =INDEX($G$45:$G$54,MATCH(H$30,$A$45:$A$54,0))*(1-$B31) -> 0.78108873 | I31: =INDEX($G$45:$G$54,MATCH(I$30,$A$45:$A$54,0))*(1-$B31) -> 0.87788121 | J31: =INDEX($G$45:$G$54,MATCH(J$30,$A$45:$A$54,0))*(1-$B31) -> 0.97467369 | ... L31: =INDEX($G$45:$G$54,MATCH(L$30,$A$45:$A$54,0))*(1-$B31) -> 1.1682586
B32: 0.125 | C32: =INDEX($G$45:$G$54,MATCH(C$30,$A$45:$A$54,0))*(1-$B32) -> 0.28887283 | D32: =INDEX($G$45:$G$54,MATCH(D$30,$A$45:$A$54,0))*(1-$B32) -> 0.38297663 | E32: =INDEX($G$45:$G$54,MATCH(E$30,$A$45:$A$54,0))*(1-$B32) -> 0.47708043 | F32: =INDEX($G$45:$G$54,MATCH(F$30,$A$45:$A$54,0))*(1-$B32) -> 0.57118423 | G32: =INDEX($G$45:$G$54,MATCH(G$30,$A$45:$A$54,0))*(1-$B32) -> 0.66528802 | H32: =INDEX($G$45:$G$54,MATCH(H$30,$A$45:$A$54,0))*(1-$B32) -> 0.75939182 | I32: =INDEX($G$45:$G$54,MATCH(I$30,$A$45:$A$54,0))*(1-$B32) -> 0.85349562 | J32: =INDEX($G$45:$G$54,MATCH(J$30,$A$45:$A$54,0))*(1-$B32) -> 0.94759942 | ... L32: =INDEX($G$45:$G$54,MATCH(L$30,$A$45:$A$54,0))*(1-$B32) -> 1.135807
B33: 0.15 | C33: =INDEX($G$45:$G$54,MATCH(C$30,$A$45:$A$54,0))*(1-$B33) -> 0.28061932 | D33: =INDEX($G$45:$G$54,MATCH(D$30,$A$45:$A$54,0))*(1-$B33) -> 0.37203444 | E33: =INDEX($G$45:$G$54,MATCH(E$30,$A$45:$A$54,0))*(1-$B33) -> 0.46344956 | F33: =INDEX($G$45:$G$54,MATCH(F$30,$A$45:$A$54,0))*(1-$B33) -> 0.55486468 | G33: =INDEX($G$45:$G$54,MATCH(G$30,$A$45:$A$54,0))*(1-$B33) -> 0.64627979 | H33: =INDEX($G$45:$G$54,MATCH(H$30,$A$45:$A$54,0))*(1-$B33) -> 0.73769491 | I33: =INDEX($G$45:$G$54,MATCH(I$30,$A$45:$A$54,0))*(1-$B33) -> 0.82911003 | J33: =INDEX($G$45:$G$54,MATCH(J$30,$A$45:$A$54,0))*(1-$B33) -> 0.92052515 | ... L33: =INDEX($G$45:$G$54,MATCH(L$30,$A$45:$A$54,0))*(1-$B33) -> 1.1033554
B34: 0.175 | C34: =INDEX($G$45:$G$54,MATCH(C$30,$A$45:$A$54,0))*(1-$B34) -> 0.27236581 | D34: =INDEX($G$45:$G$54,MATCH(D$30,$A$45:$A$54,0))*(1-$B34) -> 0.36109225 | E34: =INDEX($G$45:$G$54,MATCH(E$30,$A$45:$A$54,0))*(1-$B34) -> 0.44981869 | F34: =INDEX($G$45:$G$54,MATCH(F$30,$A$45:$A$54,0))*(1-$B34) -> 0.53854513 | G34: =INDEX($G$45:$G$54,MATCH(G$30,$A$45:$A$54,0))*(1-$B34) -> 0.62727157 | H34: =INDEX($G$45:$G$54,MATCH(H$30,$A$45:$A$54,0))*(1-$B34) -> 0.715998 | I34: =INDEX($G$45:$G$54,MATCH(I$30,$A$45:$A$54,0))*(1-$B34) -> 0.80472444 | J34: =INDEX($G$45:$G$54,MATCH(J$30,$A$45:$A$54,0))*(1-$B34) -> 0.89345088 | ... L34: =INDEX($G$45:$G$54,MATCH(L$30,$A$45:$A$54,0))*(1-$B34) -> 1.0709038
B35: 0.2 | C35: =INDEX($G$45:$G$54,MATCH(C$30,$A$45:$A$54,0))*(1-$B35) -> 0.2641123 | D35: =INDEX($G$45:$G$54,MATCH(D$30,$A$45:$A$54,0))*(1-$B35) -> 0.35015006 | E35: =INDEX($G$45:$G$54,MATCH(E$30,$A$45:$A$54,0))*(1-$B35) -> 0.43618782 | F35: =INDEX($G$45:$G$54,MATCH(F$30,$A$45:$A$54,0))*(1-$B35) -> 0.52222558 | G35: =INDEX($G$45:$G$54,MATCH(G$30,$A$45:$A$54,0))*(1-$B35) -> 0.60826334 | H35: =INDEX($G$45:$G$54,MATCH(H$30,$A$45:$A$54,0))*(1-$B35) -> 0.69430109 | I35: =INDEX($G$45:$G$54,MATCH(I$30,$A$45:$A$54,0))*(1-$B35) -> 0.78033885 | J35: =INDEX($G$45:$G$54,MATCH(J$30,$A$45:$A$54,0))*(1-$B35) -> 0.86637661 | ... L35: =INDEX($G$45:$G$54,MATCH(L$30,$A$45:$A$54,0))*(1-$B35) -> 1.0384521
B36: 0.225 | C36: =INDEX($G$45:$G$54,MATCH(C$30,$A$45:$A$54,0))*(1-$B36) -> 0.25585879 | D36: =INDEX($G$45:$G$54,MATCH(D$30,$A$45:$A$54,0))*(1-$B36) -> 0.33920787 | E36: =INDEX($G$45:$G$54,MATCH(E$30,$A$45:$A$54,0))*(1-$B36) -> 0.42255695 | F36: =INDEX($G$45:$G$54,MATCH(F$30,$A$45:$A$54,0))*(1-$B36) -> 0.50590603 | G36: =INDEX($G$45:$G$54,MATCH(G$30,$A$45:$A$54,0))*(1-$B36) -> 0.58925511 | H36: =INDEX($G$45:$G$54,MATCH(H$30,$A$45:$A$54,0))*(1-$B36) -> 0.67260419 | I36: =INDEX($G$45:$G$54,MATCH(I$30,$A$45:$A$54,0))*(1-$B36) -> 0.75595326 | J36: =INDEX($G$45:$G$54,MATCH(J$30,$A$45:$A$54,0))*(1-$B36) -> 0.83930234 | ... L36: =INDEX($G$45:$G$54,MATCH(L$30,$A$45:$A$54,0))*(1-$B36) -> 1.0060005
B37: 0.25 | C37: =INDEX($G$45:$G$54,MATCH(C$30,$A$45:$A$54,0))*(1-$B37) -> 0.24760528 | D37: =INDEX($G$45:$G$54,MATCH(D$30,$A$45:$A$54,0))*(1-$B37) -> 0.32826568 | E37: =INDEX($G$45:$G$54,MATCH(E$30,$A$45:$A$54,0))*(1-$B37) -> 0.40892608 | F37: =INDEX($G$45:$G$54,MATCH(F$30,$A$45:$A$54,0))*(1-$B37) -> 0.48958648 | G37: =INDEX($G$45:$G$54,MATCH(G$30,$A$45:$A$54,0))*(1-$B37) -> 0.57024688 | H37: =INDEX($G$45:$G$54,MATCH(H$30,$A$45:$A$54,0))*(1-$B37) -> 0.65090728 | I37: =INDEX($G$45:$G$54,MATCH(I$30,$A$45:$A$54,0))*(1-$B37) -> 0.73156767 | J37: =INDEX($G$45:$G$54,MATCH(J$30,$A$45:$A$54,0))*(1-$B37) -> 0.81222807 | ... L37: =INDEX($G$45:$G$54,MATCH(L$30,$A$45:$A$54,0))*(1-$B37) -> 0.97354887
B38: 0.275 | C38: =INDEX($G$45:$G$54,MATCH(C$30,$A$45:$A$54,0))*(1-$B38) -> 0.23935177 | D38: =INDEX($G$45:$G$54,MATCH(D$30,$A$45:$A$54,0))*(1-$B38) -> 0.31732349 | E38: =INDEX($G$45:$G$54,MATCH(E$30,$A$45:$A$54,0))*(1-$B38) -> 0.39529521 | F38: =INDEX($G$45:$G$54,MATCH(F$30,$A$45:$A$54,0))*(1-$B38) -> 0.47326693 | G38: =INDEX($G$45:$G$54,MATCH(G$30,$A$45:$A$54,0))*(1-$B38) -> 0.55123865 | H38: =INDEX($G$45:$G$54,MATCH(H$30,$A$45:$A$54,0))*(1-$B38) -> 0.62921037 | I38: =INDEX($G$45:$G$54,MATCH(I$30,$A$45:$A$54,0))*(1-$B38) -> 0.70718209 | J38: =INDEX($G$45:$G$54,MATCH(J$30,$A$45:$A$54,0))*(1-$B38) -> 0.7851538 | ... L38: =INDEX($G$45:$G$54,MATCH(L$30,$A$45:$A$54,0))*(1-$B38) -> 0.94109724
B39: 0.3 | C39: =INDEX($G$45:$G$54,MATCH(C$30,$A$45:$A$54,0))*(1-$B39) -> 0.23109826 | D39: =INDEX($G$45:$G$54,MATCH(D$30,$A$45:$A$54,0))*(1-$B39) -> 0.3063813 | E39: =INDEX($G$45:$G$54,MATCH(E$30,$A$45:$A$54,0))*(1-$B39) -> 0.38166434 | F39: =INDEX($G$45:$G$54,MATCH(F$30,$A$45:$A$54,0))*(1-$B39) -> 0.45694738 | G39: =INDEX($G$45:$G$54,MATCH(G$30,$A$45:$A$54,0))*(1-$B39) -> 0.53223042 | H39: =INDEX($G$45:$G$54,MATCH(H$30,$A$45:$A$54,0))*(1-$B39) -> 0.60751346 | I39: =INDEX($G$45:$G$54,MATCH(I$30,$A$45:$A$54,0))*(1-$B39) -> 0.6827965 | J39: =INDEX($G$45:$G$54,MATCH(J$30,$A$45:$A$54,0))*(1-$B39) -> 0.75807954 | ... L39: =INDEX($G$45:$G$54,MATCH(L$30,$A$45:$A$54,0))*(1-$B39) -> 0.90864561
B40: 0.325 | C40: =INDEX($G$45:$G$54,MATCH(C$30,$A$45:$A$54,0))*(1-$B40) -> 0.22284475 | D40: =INDEX($G$45:$G$54,MATCH(D$30,$A$45:$A$54,0))*(1-$B40) -> 0.29543911 | E40: =INDEX($G$45:$G$54,MATCH(E$30,$A$45:$A$54,0))*(1-$B40) -> 0.36803347 | F40: =INDEX($G$45:$G$54,MATCH(F$30,$A$45:$A$54,0))*(1-$B40) -> 0.44062783 | G40: =INDEX($G$45:$G$54,MATCH(G$30,$A$45:$A$54,0))*(1-$B40) -> 0.51322219 | H40: =INDEX($G$45:$G$54,MATCH(H$30,$A$45:$A$54,0))*(1-$B40) -> 0.58581655 | I40: =INDEX($G$45:$G$54,MATCH(I$30,$A$45:$A$54,0))*(1-$B40) -> 0.65841091 | J40: =INDEX($G$45:$G$54,MATCH(J$30,$A$45:$A$54,0))*(1-$B40) -> 0.73100527 | ... L40: =INDEX($G$45:$G$54,MATCH(L$30,$A$45:$A$54,0))*(1-$B40) -> 0.87619398
A43: Sensitivity Helper Calculations - PV of Incremental Revenue by Peak Share
A44: Peak Share Tested | B44: FY27 | C44: FY28 | D44: FY29 | E44: FY30 | F44: FY31 | G44: PV of Incremental Revenue (5yr sum)
A45: 0.03 | B45: =B$8*$A45*B$10-B$14 -> 0.02059 | C45: =C$8*$A45*C$10-C$14 -> 0.075686 | D45: =D$8*$A45*D$10-D$14 -> 0.12505598 | E45: =E$8*$A45*E$10-E$14 -> 0.12900936 | F45: =F$8*$A45*F$10-F$14 -> 0.091682652 | G45: =SUMPRODUCT(B45:F45,B$22:F$22) -> 0.33014038
A46: 0.035 | B46: =B$8*$A46*B$10-B$14 -> 0.025915 | C46: =C$8*$A46*C$10-C$14 -> 0.0946075 | D46: =D$8*$A46*D$10-D$14 -> 0.15934552 | E46: =E$8*$A46*E$10-E$14 -> 0.17201248 | F46: =F$8*$A46*F$10-F$14 -> 0.13752398 | G46: =SUMPRODUCT(B46:F46,B$22:F$22) -> 0.43768758
A47: 0.04 | B47: =B$8*$A47*B$10-B$14 -> 0.03124 | C47: =C$8*$A47*C$10-C$14 -> 0.113529 | D47: =D$8*$A47*D$10-D$14 -> 0.19363506 | E47: =E$8*$A47*E$10-E$14 -> 0.2150156 | F47: =F$8*$A47*F$10-F$14 -> 0.1833653 | G47: =SUMPRODUCT(B47:F47,B$22:F$22) -> 0.54523477
A48: 0.045 | B48: =B$8*$A48*B$10-B$14 -> 0.036565 | C48: =C$8*$A48*C$10-C$14 -> 0.1324505 | D48: =D$8*$A48*D$10-D$14 -> 0.2279246 | E48: =E$8*$A48*E$10-E$14 -> 0.25801872 | F48: =F$8*$A48*F$10-F$14 -> 0.22920663 | G48: =SUMPRODUCT(B48:F48,B$22:F$22) -> 0.65278197
A49: 0.05 | B49: =B$8*$A49*B$10-B$14 -> 0.04189 | C49: =C$8*$A49*C$10-C$14 -> 0.151372 | D49: =D$8*$A49*D$10-D$14 -> 0.26221415 | E49: =E$8*$A49*E$10-E$14 -> 0.30102184 | F49: =F$8*$A49*F$10-F$14 -> 0.27504796 | G49: =SUMPRODUCT(B49:F49,B$22:F$22) -> 0.76032917
...

Sheet Option_B_LensExpansion
A1: Option B: Contact Lens Parameter Expansion - Model
A2: ($ in billions unless otherwise noted)
A4: Active Scenario: | B4: Base
A6: Driver | B6: FY27 | C6: FY28 | D6: FY29 | E6: FY30 | F6: FY31
A7: Toric Segment CAGR | B7: 0.048
A8: Toric Segment Size ($B) | B8: 4.4 | C8: =B8*(1+$B$7) -> 4.6112 | D8: =C8*(1+$B$7) -> 4.8325376 | E8: =D8*(1+$B$7) -> 5.0644994 | F8: =E8*(1+$B$7) -> 5.3075954
A9: Active Share-of-Segment Gain (resolved from toggle) | B9: =INDEX(Cover_Assumptions!B25:D25, MATCH($B$4,Cover_Assumptions!B24:D24,0)) -> 0.0075
A10: Ramp % of Peak Share Gain | B10: 0.4 | C10: 0.8 | D10: 1 | E10: 1 | F10: 1
A11: Invest Case Revenue ($B) | B11: =B8*($B$12+$B$9*B10) -> 0.8052 | C11: =C8*($B$12+$B$9*C10) -> 0.8576832 | D11: =D8*($B$12+$B$9*D10) -> 0.9061008 | E11: =E8*($B$12+$B$9*E10) -> 0.94959364 | F11: =F8*($B$12+$B$9*F10) -> 0.99517413
A12: Alcon's Current Toric Share | B12: =Cover_Assumptions!B28 -> 0.18
A13: Do-Nothing Case Revenue ($B) | B13: =B8*$B$12 -> 0.792 | C13: =C8*$B$12 -> 0.830016 | D13: =D8*$B$12 -> 0.86985677 | E13: =E8*$B$12 -> 0.91160989 | F13: =F8*$B$12 -> 0.95536717
A15: Incremental Revenue ($B) | B15: =B11-B13 -> 0.0132 | C15: =C11-C13 -> 0.0276672 | D15: =D11-D13 -> 0.036244032 | E15: =E11-E13 -> 0.037983746 | F15: =F11-F13 -> 0.039806965
A16: Commercial Spend ($B) | B16: =B15*Cover_Assumptions!$B$27 -> 0.00165 | C16: =C15*Cover_Assumptions!$B$27 -> 0.0034584 | D16: =D15*Cover_Assumptions!$B$27 -> 0.004530504 | E16: =E15*Cover_Assumptions!$B$27 -> 0.0047479682 | F16: =F15*Cover_Assumptions!$B$27 -> 0.0049758707
A17: Net Incremental Cash Flow ($B) | B17: =B15-B16 -> 0.01155 | C17: =C15-C16 -> 0.0242088 | D17: =D15-D16 -> 0.031713528 | E17: =E15-E16 -> 0.033235777 | F17: =F15-F16 -> 0.034831095
A19: Year Index | B19: 1 | C19: =B19+1 -> 2 | D19: =C19+1 -> 3 | E19: =D19+1 -> 4 | F19: =E19+1 -> 5
A20: NPV & Returns
A21: Discount Factor | B21: =1/(1+Cover_Assumptions!$B$10)^B19 -> 0.91743119 | C21: =1/(1+Cover_Assumptions!$B$10)^C19 -> 0.84167999 | D21: =1/(1+Cover_Assumptions!$B$10)^D19 -> 0.77218348 | E21: =1/(1+Cover_Assumptions!$B$10)^E19 -> 0.70842521 | F21: =1/(1+Cover_Assumptions!$B$10)^F19 -> 0.64993139
A22: PV of Net Incremental Cash Flow ($B) | B22: =B17*B21 -> 0.01059633 | C22: =C17*C21 -> 0.020376063 | D22: =D17*D21 -> 0.024488662 | E22: =E17*E21 -> 0.023545063 | F22: =F17*F21 -> 0.022637822
A23: Cumulative PV of Net Incremental Cash Flow | B23: =B22 -> 0.01059633 | C23: =C22+B23 -> 0.030972393 | D23: =D22+C23 -> 0.055461055 | E23: =E22+D23 -> 0.079006118 | F23: =F22+E23 -> 0.10164394
A25: NPV - Option B (Lens Expansion), 5-Year ($B) | B25: =SUM(B22:F22) -> 0.10164394
A28: Sensitivity Analysis - NPV ($B) vs. Share-of-Segment Gain & Commercial Spend Ratio
B29: =B25 -> 0.10164394 | C29: 0.0025 | D29: 0.005 | E29: 0.0075 | F29: 0.01 | G29: 0.0125 | H29: 0.015
B30: 0.05 | C30: =INDEX($G$40:$G$45,MATCH(C$29,$A$40:$A$45,0))*(1-$B30) -> 0.036785426 | D30: =INDEX($G$40:$G$45,MATCH(D$29,$A$40:$A$45,0))*(1-$B30) -> 0.073570851 | E30: =INDEX($G$40:$G$45,MATCH(E$29,$A$40:$A$45,0))*(1-$B30) -> 0.11035628 | F30: =INDEX($G$40:$G$45,MATCH(F$29,$A$40:$A$45,0))*(1-$B30) -> 0.1471417 | G30: =INDEX($G$40:$G$45,MATCH(G$29,$A$40:$A$45,0))*(1-$B30) -> 0.18392713 | H30: =INDEX($G$40:$G$45,MATCH(H$29,$A$40:$A$45,0))*(1-$B30) -> 0.22071255
B31: 0.075 | C31: =INDEX($G$40:$G$45,MATCH(C$29,$A$40:$A$45,0))*(1-$B31) -> 0.035817388 | D31: =INDEX($G$40:$G$45,MATCH(D$29,$A$40:$A$45,0))*(1-$B31) -> 0.071634776 | E31: =INDEX($G$40:$G$45,MATCH(E$29,$A$40:$A$45,0))*(1-$B31) -> 0.10745216 | F31: =INDEX($G$40:$G$45,MATCH(F$29,$A$40:$A$45,0))*(1-$B31) -> 0.14326955 | G31: =INDEX($G$40:$G$45,MATCH(G$29,$A$40:$A$45,0))*(1-$B31) -> 0.17908694 | H31: =INDEX($G$40:$G$45,MATCH(H$29,$A$40:$A$45,0))*(1-$B31) -> 0.21490433
B32: 0.1 | C32: =INDEX($G$40:$G$45,MATCH(C$29,$A$40:$A$45,0))*(1-$B32) -> 0.034849351 | D32: =INDEX($G$40:$G$45,MATCH(D$29,$A$40:$A$45,0))*(1-$B32) -> 0.069698701 | E32: =INDEX($G$40:$G$45,MATCH(E$29,$A$40:$A$45,0))*(1-$B32) -> 0.10454805 | F32: =INDEX($G$40:$G$45,MATCH(F$29,$A$40:$A$45,0))*(1-$B32) -> 0.1393974 | G32: =INDEX($G$40:$G$45,MATCH(G$29,$A$40:$A$45,0))*(1-$B32) -> 0.17424675 | H32: =INDEX($G$40:$G$45,MATCH(H$29,$A$40:$A$45,0))*(1-$B32) -> 0.2090961
B33: 0.125 | C33: =INDEX($G$40:$G$45,MATCH(C$29,$A$40:$A$45,0))*(1-$B33) -> 0.033881313 | D33: =INDEX($G$40:$G$45,MATCH(D$29,$A$40:$A$45,0))*(1-$B33) -> 0.067762626 | E33: =INDEX($G$40:$G$45,MATCH(E$29,$A$40:$A$45,0))*(1-$B33) -> 0.10164394 | F33: =INDEX($G$40:$G$45,MATCH(F$29,$A$40:$A$45,0))*(1-$B33) -> 0.13552525 | G33: =INDEX($G$40:$G$45,MATCH(G$29,$A$40:$A$45,0))*(1-$B33) -> 0.16940657 | H33: =INDEX($G$40:$G$45,MATCH(H$29,$A$40:$A$45,0))*(1-$B33) -> 0.20328788
B34: 0.15 | C34: =INDEX($G$40:$G$45,MATCH(C$29,$A$40:$A$45,0))*(1-$B34) -> 0.032913276 | D34: =INDEX($G$40:$G$45,MATCH(D$29,$A$40:$A$45,0))*(1-$B34) -> 0.065826551 | E34: =INDEX($G$40:$G$45,MATCH(E$29,$A$40:$A$45,0))*(1-$B34) -> 0.098739827 | F34: =INDEX($G$40:$G$45,MATCH(F$29,$A$40:$A$45,0))*(1-$B34) -> 0.1316531 | G34: =INDEX($G$40:$G$45,MATCH(G$29,$A$40:$A$45,0))*(1-$B34) -> 0.16456638 | H34: =INDEX($G$40:$G$45,MATCH(H$29,$A$40:$A$45,0))*(1-$B34) -> 0.19747965
B35: 0.175 | C35: =INDEX($G$40:$G$45,MATCH(C$29,$A$40:$A$45,0))*(1-$B35) -> 0.031945238 | D35: =INDEX($G$40:$G$45,MATCH(D$29,$A$40:$A$45,0))*(1-$B35) -> 0.063890476 | E35: =INDEX($G$40:$G$45,MATCH(E$29,$A$40:$A$45,0))*(1-$B35) -> 0.095835714 | F35: =INDEX($G$40:$G$45,MATCH(F$29,$A$40:$A$45,0))*(1-$B35) -> 0.12778095 | G35: =INDEX($G$40:$G$45,MATCH(G$29,$A$40:$A$45,0))*(1-$B35) -> 0.15972619 | H35: =INDEX($G$40:$G$45,MATCH(H$29,$A$40:$A$45,0))*(1-$B35) -> 0.19167143
A38: Sensitivity Helper Calculations - PV of Incremental Revenue by Share-of-Segment Gain
A39: Share Gain Tested | B39: FY27 | C39: FY28 | D39: FY29 | E39: FY30 | F39: FY31 | G39: PV of Incremental Revenue (5yr sum)
A40: 0.0025 | B40: =B$8*($B$12+$A40*B$10)-B$13 -> 0.0044 | C40: =C$8*($B$12+$A40*C$10)-C$13 -> 0.0092224 | D40: =D$8*($B$12+$A40*D$10)-D$13 -> 0.012081344 | E40: =E$8*($B$12+$A40*E$10)-E$13 -> 0.012661249 | F40: =F$8*($B$12+$A40*F$10)-F$13 -> 0.013268988 | G40: =SUMPRODUCT(B40:F40,$B$21:$F$21) -> 0.038721501
A41: 0.005 | B41: =B$8*($B$12+$A41*B$10)-B$13 -> 0.0088 | C41: =C$8*($B$12+$A41*C$10)-C$13 -> 0.0184448 | D41: =D$8*($B$12+$A41*D$10)-D$13 -> 0.024162688 | E41: =E$8*($B$12+$A41*E$10)-E$13 -> 0.025322497 | F41: =F$8*($B$12+$A41*F$10)-F$13 -> 0.026537977 | G41: =SUMPRODUCT(B41:F41,$B$21:$F$21) -> 0.077443002
A42: 0.0075 | B42: =B$8*($B$12+$A42*B$10)-B$13 -> 0.0132 | C42: =C$8*($B$12+$A42*C$10)-C$13 -> 0.0276672 | D42: =D$8*($B$12+$A42*D$10)-D$13 -> 0.036244032 | E42: =E$8*($B$12+$A42*E$10)-E$13 -> 0.037983746 | F42: =F$8*($B$12+$A42*F$10)-F$13 -> 0.039806965 | G42: =SUMPRODUCT(B42:F42,$B$21:$F$21) -> 0.1161645
A43: 0.01 | B43: =B$8*($B$12+$A43*B$10)-B$13 -> 0.0176 | C43: =C$8*($B$12+$A43*C$10)-C$13 -> 0.0368896 | D43: =D$8*($B$12+$A43*D$10)-D$13 -> 0.048325376 | E43: =E$8*($B$12+$A43*E$10)-E$13 -> 0.050644994 | F43: =F$8*($B$12+$A43*F$10)-F$13 -> 0.053075954 | G43: =SUMPRODUCT(B43:F43,$B$21:$F$21) -> 0.154886
A44: 0.0125 | B44: =B$8*($B$12+$A44*B$10)-B$13 -> 0.022 | C44: =C$8*($B$12+$A44*C$10)-C$13 -> 0.046112 | D44: =D$8*($B$12+$A44*D$10)-D$13 -> 0.06040672 | E44: =E$8*($B$12+$A44*E$10)-E$13 -> 0.063306243 | F44: =F$8*($B$12+$A44*F$10)-F$13 -> 0.066344942 | G44: =SUMPRODUCT(B44:F44,$B$21:$F$21) -> 0.1936075
A45: 0.015 | B45: =B$8*($B$12+$A45*B$10)-B$13 -> 0.0264 | C45: =C$8*($B$12+$A45*C$10)-C$13 -> 0.0553344 | D45: =D$8*($B$12+$A45*D$10)-D$13 -> 0.072488064 | E45: =E$8*($B$12+$A45*E$10)-E$13 -> 0.075967491 | F45: =F$8*($B$12+$A45*F$10)-F$13 -> 0.079613931 | G45: =SUMPRODUCT(B45:F45,$B$21:$F$21) -> 0.232329

Sheet Portfolio_Comparison
A1: Portfolio Comparison - Option A vs. Option B
A2: Market Attractiveness & Right-to-Win Assessment, NPV/Returns Summary, and Sequencing Recommendation
A4: Market Attractiveness & Right-to-Win Assessment
A5: Dimension | B5: Criterion | C5: Option A: Tryptyr | D5: Option B: Lens Expansion | E5: Rationale
A6: Market Attractiveness | B6: Market size & growth | C6: High | D6: Low-Medium | E6: Global DED market $7.1B growing 6.6% CAGR to $11.1B by 2033 vs. toric segment $4.4B growing only 4.8% CAGR — already mature/saturated
B7: Competitive Intensity | C7: Low-Medium | D7: Low | E7: Tryptyr is first-in-class (TRPM8) with differentiated mechanism vs. Xiidra/Restasis/Cequa/Miebo; toric segment has 4 established competitors (J&J, CooperVision, B+L, Alcon) all fighting for the same mature gap
B8: Profitability / margin potential | C8: Medium-High | D8: Medium | E8: Specialty pharma margins typically exceed contact lens category margins even after Tryptyr's higher commercial spend ratio (20-25% vs. 10-15%); reasoned inference, not directly sourced — no hard margin data available for either segment in source materials
B9: Demand durability (low adoption/retention risk = more attractive) | C9: Medium | D9: High | E9: ~50% of Tryptyr trial patients reported instillation-site pain, but <1% discontinued therapy because of it (Source: Alcon prescribing information / COMET trial data) — suggesting the tolerability signal is real but largely manageable rather than a major adoption-killing risk; toric lens expansion carries even less comparable risk given 99% first-fit success rate and no new tolerability profile to introduce
A10: Right to Win | B10: Existing capabilities / brand strength | C10: Medium | D10: High | E10: Tryptyr is a brand-new mechanism requiring new prescriber trust/behavior, though Alcon has some ocular-health presence via Systane; PRECISION1 was already the fastest-growing US daily disposable brand pre-toric-launch, indicating strong existing brand equity to extend from
B11: Distribution / ECP relationships | C11: Medium | D11: High | E11: Tryptyr requires building new sales force/DTC infrastructure and prescriber relationships specifically for this mechanism (reflected in its higher 20-25% commercial spend ratio); lens expansion leverages already-established ECP fitting relationships and distribution (reflected in its lower 10-15% ratio)
B12: Execution risk / complexity | C12: Medium-Low | D12: High | E12: Tryptyr requires new prescribing behavior change (de-novo clinical decision) and carries the tolerability risk noted above; lens expansion requires no behavior change beyond an existing fitting workflow, with 99% first-fit success demonstrated in trials
B13: Defensibility of share gained (patent/exclusivity) | C13: High | D13: Low | E13: Tryptyr has an estimated 5-7 year patent-protected window (third-party analyst estimate, not Alcon-disclosed) limiting direct molecular competition; toric lens parameter expansion has no equivalent exclusivity — competitors can respond with their own expanded SKU ranges without a comparable legal barrier
A15: Overall Assessment | B15: Overall placement | C15: Market Attractiveness: Medium-High | Right-to-Win: Medium | D15: Market Attractiveness: Low-Medium | Right-to-Win: High | E15: Option A offers a larger, faster-growing opportunity but requires building new prescriber trust/behavior in a moderately competitive field; Option B offers a smaller, more mature opportunity but with near-ideal execution conditions (existing relationships, minimal adoption friction, defensible distribution) — though without Option A's patent-protected exclusivity once share is won
A17: Financial Summary - NPV by Scenario ($B)
A18: Driver/Scenario | B18: Option A: Tryptyr | C18: Option B: Lens Expansion
A19: Base | B19: 0.589 | C19: 0.102
A20: Upside | B20: 1.006 | C20: 0.203
A21: Downside | B21: 0.256 | C21: 0.034
A22: Payback Period | B22: Immediate by construction — not a true risk signal (see note)
A24: Sequencing & Funding Recommendation
A25: Recommendation: Fund both options — they are independent, NPV-positive across all scenarios (including Downside), and target genuinely different parts of the Vision Care portfolio. If capacity allows, pursue both in parallel starting FY27. If incremental investment capacity is constrained and a sequencing choice is required, prioritize Option A (Tryptyr) first. While Option B (Lens Expansion) scores higher on Right-to-Win — lower execution risk, existing ECP relationships, minimal adoption friction — Option A carries a materially higher cost of delay: its 5-7 year patent-protected window began running at launch (Q3 2025) and erodes regardless of investment timing, while Tryptyr's tolerability profile (50% adverse-event rate, but <1% discontinuation) is better understood and lower-risk than initially appears. Option B's opportunity, by contrast, is durable — the toric segment's slower, more stable growth (4.8% CAGR) means delaying this investment by even 1-2 quarters does not meaningfully shrink the total addressable opportunity the way delaying Option A would shrink its patent-protected capture window. In short: Right-to-Win favors Option B's ease of execution, but cost-of-delay favors Option A's urgency — and under a binding capacity constraint, urgency should take priority over comfort, since Option A's opportunity decays in a way Option B's does not.
